Workbook

Sheet DataActual6m
A1: Date | B1: BIDU | C1: TME | D1: VIPS | E1: FTCH | F1: IQ | G1: PARA | H1: DISCA | I1: GSX | J1: NDX | K1: S&P
A2: 44277 | B2: 266.13 | C2: 30.87 | D2: 45.25 | E2: 62 | F2: 28.04 | G2: 100.34 | H2: 74.65 | I2: 83.79 | J2: 13086.51 | K2: 3940.59
A3: 44274 | B3: 257.47 | C3: 30.42 | D3: 45.45 | E3: 59.880001 | F3: 27.77 | G3: 97.35 | H3: 77.27 | I3: 86.6 | J3: 12866.99 | K3: 3913.1
A4: 44273 | B4: 264.85 | C4: 28.52 | D4: 44.46 | E4: 59.5 | F4: 26.63 | G4: 96.76 | H4: 75.95 | I4: 89.68 | J4: 12789.14 | K4: 3915.46
A5: 44272 | B5: 277.13 | C5: 27.9 | D5: 44.11 | E5: 60.77 | F5: 26.03 | G5: 92.34 | H5: 74.07 | I5: 92.67 | J5: 13202.38 | K5: 3974.12
A6: 44271 | B6: 266.78 | C6: 26.45 | D6: 42.92 | E6: 59.25 | F6: 25.5 | G6: 96.24 | H6: 75.81 | I6: 89.3 | J6: 13152.28 | K6: 3962.71
A7: 44270 | B7: 265.53 | C7: 26.36 | D7: 41.7 | E7: 58.259998 | F7: 25.14 | G7: 96.33 | H7: 73.67 | I7: 89.16 | J7: 13082.54 | K7: 3968.94
A8: 44267 | B8: 264.25 | C8: 26.49 | D8: 42.2 | E8: 59.5 | F8: 26.44 | G8: 94.94 | H8: 71.1 | I8: 84.88 | J8: 12937.29 | K8: 3943.34
A9: 44266 | B9: 272.38 | C9: 27.78 | D9: 42.41 | E9: 59.84 | F9: 27.69 | G9: 86.28 | H9: 66.97 | I9: 82.05 | J9: 13052.9 | K9: 3939.34
A10: 44265 | B10: 255.14 | C10: 27.35 | D10: 42.01 | E10: 56.470001 | F10: 27.83 | G10: 82.89 | H10: 65.82 | I10: 81.01 | J10: 12752.07 | K10: 3898.81
A11: 44264 | B11: 264.28 | C11: 26.69 | D11: 41.59 | E11: 56.240002 | F11: 27.09 | G11: 79.66 | H11: 63.01 | I11: 88.62 | J11: 12794.49 | K11: 3875.44
A12: 44263 | B12: 232.68 | C12: 25.32 | D12: 40.64 | E12: 53.5 | F12: 25.76 | G12: 83.66 | H12: 67.25 | I12: 85.94 | J12: 12299.08 | K12: 3821.35
A13: 44260 | B13: 261.72 | C13: 26.15 | D13: 41.22 | E13: 55.509998 | F13: 26.07 | G13: 74.24 | H13: 64.25 | I13: 91.39 | J13: 12668.51 | K13: 3841.94
... A125: 44097 | B125: 122.92 | C125: 14.73 | D125: 16.92 | E125: 23.940001 | F125: 23.66 | G125: 28.82 | H125: 21.13 | I125: 106 | J125: 10833.33 | K125: 3236.92

Sheet BIDU
A1: Date | B1: Last Price | C1: Volume | D1: SMAVG (15)
A2: 45855 | C2: 33901 | D2: 3548052
A3: 45854 | B3: 86.32 | C3: 13675625 | D3: 3640900
A4: 45853 | B4: 93.3 | C4: 12043236 | D4: 2898483
A5: 45852 | B5: 85.87 | C5: 2491125 | D5: 2312360
A6: 45849 | B6: 86.93 | C6: 2451782 | D6: 2294501
A7: 45848 | B7: 88.44 | C7: 1726516 | D7: 2242658
A8: 45847 | B8: 88.66 | C8: 2310411 | D8: 2231867
A9: 45846 | B9: 90.28 | C9: 2058583 | D9: 2225358
A10: 45845 | B10: 89.79 | C10: 6788432 | D10: 2249110
A11: 45841 | B11: 86.35 | C11: 1167623 | D11: 1914277
A12: 45840 | B12: 86.44 | C12: 1699704 | D12: 1963072
A13: 45839 | B13: 86.04 | C13: 1631875 | D13: 2011556
A14: 45838 | B14: 85.76 | C14: 1843567 | D14: 2129466
... A2464: 42277 | B2464: 137.41 | C2464: 2625595 | D2464: 4032257
A2465: 42276 | B2465: 136.68 | C2465: 3389072
A2466: 42275 | B2466: 133.06 | C2466: 4045377
A2467: 42272 | B2467: 134.34 | C2467: 3530502
A2468: 42271 | B2468: 132.59 | C2468: 4840455
A2469: 42270 | B2469: 132.37 | C2469: 4571179
A2470: 42269 | B2470: 136.12 | C2470: 4429042
A2471: 42268 | B2471: 140.84 | C2471: 2888464
A2472: 42265 | B2472: 142.57 | C2472: 3282604
A2473: 42264 | B2473: 147.06 | C2473: 5176578
A2474: 42263 | B2474: 150.35 | C2474: 4838111
A2475: 42262 | B2475: 141.4 | C2475: 4437632
A2476: 42261 | B2476: 141.27 | C2476: 3794494
... A2478: 42257 | B2478: 146.75 | C2478: 3710333

Sheet TME
A1: Date | B1: Last Price | C1: Volume | D1: SMAVG (15)
A2: 45855
A3: 45854 | B3: 21.44 | C3: 1124606 | D3: 1434599
A4: 45853 | B4: 21.29 | C4: 1846509 | D4: 1436734
A5: 45852 | B5: 20.67 | C5: 1846219 | D5: 1384125
A6: 45849 | B6: 19.79 | C6: 1165558 | D6: 1928076
A7: 45848 | B7: 20 | C7: 1164550 | D7: 1936797
A8: 45847 | B8: 20.35 | C8: 1400073 | D8: 1935673
A9: 45846 | B9: 20.29 | C9: 2225796 | D9: 1950950
A10: 45845 | B10: 20.04 | C10: 1928267 | D10: 2227332
A11: 45841 | B11: 19.46 | C11: 929237 | D11: 2205199
A12: 45840 | B12: 19.17 | C12: 747384 | D12: 2269920
A13: 45839 | B13: 19.24 | C13: 1221399 | D13: 2371499
A14: 45838 | B14: 19.49 | C14: 1936908 | D14: 2433265
... A1644: 43468 | B1644: 12.44 | C1644: 1389253 | D1644: 3179038
A1645: 43467 | B1645: 13 | C1645: 744001
A1646: 43465 | B1646: 13.22 | C1646: 658052
A1647: 43462 | B1647: 13.4 | C1647: 825254
A1648: 43461 | B1648: 13.51 | C1648: 2071776
A1649: 43460 | B1649: 12.48 | C1649: 1109643
A1650: 43458 | B1650: 12 | C1650: 859797
A1651: 43455 | B1651: 12.19 | C1651: 2115673
A1652: 43454 | B1652: 12.19 | C1652: 1338942
A1653: 43453 | B1653: 12.18 | C1653: 1716546
A1654: 43452 | B1654: 12.3 | C1654: 1522214
A1655: 43451 | B1655: 12.13 | C1655: 2719214
A1656: 43448 | B1656: 12.81 | C1656: 4713621
... A1658: 43446 | B1658: 14 | C1658: 22093064

Sheet VIPS
A1: Date | B1: Last Price | C1: Volume | D1: SMAVG (15)
A2: 45855
A3: 45854 | B3: 15.12 | C3: 632117 | D3: 812591
A4: 45853 | B4: 15.58 | C4: 1634971 | D4: 811060
A5: 45852 | B5: 15.11 | C5: 579810 | D5: 768844
A6: 45849 | B6: 15.2 | C6: 1383408 | D6: 823091
A7: 45848 | B7: 15.01 | C7: 451239 | D7: 770843
A8: 45847 | B8: 15.07 | C8: 860782 | D8: 776017
A9: 45846 | B9: 14.96 | C9: 1041532 | D9: 752409
A10: 45845 | B10: 14.96 | C10: 871040 | D10: 815689
A11: 45841 | B11: 14.99 | C11: 294705 | D11: 796651
A12: 45840 | B12: 15.07 | C12: 1007204 | D12: 818214
A13: 45839 | B13: 15.1 | C13: 536269 | D13: 795922
A14: 45838 | B14: 15.05 | C14: 761202 | D14: 794364
... A2528: 42185 | B2528: 22.25 | C2528: 1419519 | D2528: 1233500
A2529: 42184 | B2529: 21.54 | C2529: 1579265
A2530: 42181 | B2530: 21.97 | C2530: 1871906
A2531: 42180 | B2531: 22.64 | C2531: 924300
A2532: 42179 | B2532: 23.13 | C2532: 922526
A2533: 42178 | B2533: 23.81 | C2533: 1172377
A2534: 42177 | B2534: 23.21 | C2534: 1340813
A2535: 42174 | B2535: 23 | C2535: 1944395
A2536: 42173 | B2536: 24.85 | C2536: 1688021
A2537: 42172 | B2537: 25.93 | C2537: 1021725
A2538: 42171 | B2538: 25.29 | C2538: 655524
A2539: 42170 | B2539: 24.99 | C2539: 989233
A2540: 42167 | B2540: 25.35 | C2540: 953363
... A2542: 42165 | B2542: 24.32 | C2542: 978202

Sheet FTCH
A1: Date | B1: Last Price | C1: Volume | D1: SMAVG (15)
A2: 45855
A3: 45854 | B3: 1e-06 | C3: 1367602 | D3: 119205
A4: 45853 | B4: 1e-06 | C4: 6000 | D4: 29013
A5: 45852 | B5: 1e-06 | C5: 25752 | D5: 28725
A6: 45849 | B6: 1e-06 | C6: 2053 | D6: 27042
A7: 45848 | B7: 1e-06 | C7: 1763 | D7: 26959
A8: 45847 | B8: 1e-06 | C8: 30322 | D8: 26845
A9: 45846 | B9: 1e-06 | C9: 443 | D9: 24937
A10: 45845 | B10: 1e-06 | C10: 577 | D10: 24927
A11: 45841 | B11: 1e-06 | C11: 140049 | D11: 24890
A12: 45840 | B12: 1e-06 | C12: 33700 | D12: 15774
A13: 45839 | B13: 1e-06 | C13: 11288 | D13: 13527
A14: 45838 | B14: 1e-06 | C14: 2487 | D14: 14835
... A21: 45826 | B21: 1e-06 | C21: 808 | D21: 255066
A22: 45825 | C22: 65 | D22: 318175
A23: 45824 | B23: 1e-06 | C23: 1689 | D23: 318465
A24: 45820 | C24: 299 | D24: 319127
A25: 45819 | C25: 28 | D25: 319451
A26: 45818 | B26: 1e-06 | C26: 3300 | D26: 319561
A27: 45814 | C27: 1 | D27: 319356
A28: 45813 | B28: 1e-06 | C28: 30908 | D28: 319359
A29: 45812 | C29: 16 | D29: 321239
A30: 45811 | B30: 1e-06 | C30: 4015 | D30: 332454
A31: 45810 | B31: 1e-06 | C31: 3487808 | D31: 332204
A32: 45807 | B32: 1e-06 | C32: 310 | D32: 100113
A33: 45806 | B33: 1e-06 | C33: 9750 | D33: 100110
A34: 45805 | B34: 1e-06 | C34: 7775 | D34: 99461
A35: 45804 | B35: 1e-06 | C35: 279219 | D35: 98965
A36: 45800 | B36: 0.0001 | C36: 947435 | D36: 80983
A37: 45799 | B37: 1e-06 | C37: 4418 | D37: 18032
A38: 45798 | B38: 1e-06 | C38: 11623 | D38: 17743
A39: 45797 | B39: 1e-06 | C39: 5156 | D39: 16995
A40: 45796 | B40: 1e-06 | C40: 1678 | D40: 17181
A41: 45793 | B41: 1e-06 | C41: 223 | D41: 34636
A42: 45792 | C42: 50 | D42: 34628
A43: 45791 | B43: 1e-06 | C43: 59111 | D43: 34728
A44: 45790 | B44: 1e-06 | C44: 168233 | D44: 30789
A45: 45789 | B45: 1e-06 | C45: 270 | D45: 19697
A46: 45786 | B46: 1e-06 | C46: 6450 | D46: 24986
...

Sheet IQ
A1: Date | B1: Last Price | C1: Volume | D1: SMAVG (15)
A2: 45855 | C2: 2172 | D2: 15755685
A3: 45854 | B3: 1.86 | C3: 15988130 | D3: 17566554
A4: 45853 | B4: 1.86 | C4: 33779664 | D4: 17719366
A5: 45852 | B5: 1.79 | C5: 21725498 | D5: 16480508
A6: 45849 | B6: 1.83 | C6: 10672681 | D6: 16103707
A7: 45848 | B7: 1.83 | C7: 9873843 | D7: 16270873
A8: 45847 | B8: 1.82 | C8: 15635830 | D8: 16244175
A9: 45846 | B9: 1.83 | C9: 24727392 | D9: 16681015
A10: 45845 | B10: 1.77 | C10: 22048744 | D10: 16976664
A11: 45841 | B11: 1.78 | C11: 18023438 | D11: 16362940
A12: 45840 | B12: 1.75 | C12: 12014799 | D12: 16286024
A13: 45839 | B13: 1.76 | C13: 12471197 | D13: 17587102
A14: 45838 | B14: 1.77 | C14: 11473002 | D14: 19010774
... A1822: 43209 | B1822: 18.34 | C1822: 5656715 | D1822: 12681094
A1823: 43208 | B1823: 18.95 | C1823: 5473804
A1824: 43207 | B1824: 19.63 | C1824: 9237189
A1825: 43206 | B1825: 19.74 | C1825: 6404784
A1826: 43203 | B1826: 19.34 | C1826: 10007680
A1827: 43202 | B1827: 19.04 | C1827: 12292724
A1828: 43201 | B1828: 18.07 | C1828: 9231082
A1829: 43200 | B1829: 17.41 | C1829: 7035004
A1830: 43199 | B1830: 16.41 | C1830: 4265722
A1831: 43196 | B1831: 16.02 | C1831: 3493753
A1832: 43195 | B1832: 16.04 | C1832: 4216494
A1833: 43194 | B1833: 15.67 | C1833: 9866580
A1834: 43193 | B1834: 16 | C1834: 7994116
... A1836: 43188 | B1836: 15.55 | C1836: 79752928
A1837: 43187 | B1837: 18

Sheet Para
A1: Date | B1: Last Price | C1: Volume | D1: SMAVG (15)
A2: 45657 | B2: 10.46 | C2: 9559040 | D2: 9060452
A3: 45656 | B3: 10.34 | C3: 8242076 | D3: 9160841
A4: 45653 | B4: 10.4 | C4: 5766166 | D4: 9118688
A5: 45652 | B5: 10.44 | C5: 6850469 | D5: 9204368
A6: 45650 | B6: 10.42 | C6: 4116209 | D6: 9285121
A7: 45649 | B7: 10.35 | C7: 9671823 | D7: 9405626
A8: 45646 | B8: 10.66 | C8: 18990852 | D8: 9178558
A9: 45645 | B9: 10.58 | C9: 9067332 | D9: 8155956
A10: 45644 | B10: 10.68 | C10: 12328512 | D10: 8302554
A11: 45643 | B11: 10.81 | C11: 7242394 | D11: 8350543
A12: 45642 | B12: 10.98 | C12: 8274681 | D12: 11547151
A13: 45639 | B13: 11.22 | C13: 5618791 | D13: 11745022
... A2394: 42185 | B2394: 55.5 | C2394: 4208489 | D2394: 4070369
A2395: 42184 | B2395: 55.33 | C2395: 4763443
A2396: 42181 | B2396: 57 | C2396: 4212115
A2397: 42180 | B2397: 57.13 | C2397: 5513678
A2398: 42179 | B2398: 56.77 | C2398: 4560914
A2399: 42178 | B2399: 58.09 | C2399: 2756709
A2400: 42177 | B2400: 58.34 | C2400: 2237435
A2401: 42174 | B2401: 58.06 | C2401: 4050838
A2402: 42173 | B2402: 58.51 | C2402: 3088047
A2403: 42172 | B2403: 58 | C2403: 4116984
A2404: 42171 | B2404: 57.69 | C2404: 3490428
A2405: 42170 | B2405: 58.14 | C2405: 3556580
A2406: 42167 | B2406: 58.49 | C2406: 3563749
... A2408: 42165 | B2408: 59.49 | C2408: 5299114

Sheet DISCA
A1: Date | B1: Last Price | C1: Volume | D1: SMAVG (15)
A2: 45859
A3: 44657 | B3: 23.92 | C3: 1000 | D3: 2065
A4: 44656 | B4: 24.42 | C4: 2000 | D4: 2299
A5: 44655 | B5: 25.8 | C5: 1000 | D5: 2585
A6: 44649 | B6: 26.25 | C6: 4147 | D6: 2919
A7: 44648 | B7: 25.58 | C7: 1300 | D7: 2762
A8: 44645 | B8: 27.35 | C8: 1300 | D8: 2802
A9: 44644 | B9: 27.12 | C9: 3000 | D9: 2782
A10: 44643 | B10: 26.62 | C10: 1500 | D10: 2642
A11: 44642 | B11: 26.87 | C11: 2000 | D11: 2615
A12: 44631 | B12: 23.99 | C12: 495 | D12: 2509
A13: 44630 | B13: 25.08 | C13: 990 | D13: 2769
A14: 44629 | B14: 25.37 | C14: 1287 | D14: 2803
... A90: 44378 | B90: 31.2 | C90: 1485 | D90: 6250
A91: 43983 | B91: 21.95
A92: 43984 | B92: 21.84
A93: 43985 | B93: 22.28
A94: 43986 | B94: 23.09
A95: 43987 | B95: 24.78
A96: 43990 | B96: 26.16
A97: 43991 | B97: 23.88
A98: 43992 | B98: 23.17
A99: 43993 | B99: 22.34
A100: 43994 | B100: 22.08
A101: 43997 | B101: 22.75
A102: 43998 | B102: 22.27
... A364: 44021 | B364: 19.25

Sheet GSX
A1: Date | B1: Last Price | C1: Volume | D1: SMAVG (15)
A2: 45855 | C2: 458 | D2: 704741
A3: 45854 | B3: 3.84 | C3: 811253 | D3: 766286
A4: 45853 | B4: 3.99 | C4: 2306223 | D4: 758678
A5: 45852 | B5: 3.59 | C5: 274301 | D5: 719729
A6: 45849 | B6: 3.56 | C6: 359118 | D6: 783331
A7: 45848 | B7: 3.58 | C7: 274032 | D7: 818667
A8: 45847 | B8: 3.65 | C8: 616433 | D8: 836340
A9: 45846 | B9: 3.6 | C9: 905146 | D9: 841437
A10: 45845 | B10: 3.45 | C10: 557692 | D10: 841719
A11: 45841 | B11: 3.53 | C11: 506907 | D11: 845582
A12: 45840 | B12: 3.58 | C12: 707888 | D12: 856361
A13: 45839 | B13: 3.58 | C13: 701041 | D13: 849307
A14: 45838 | B14: 3.61 | C14: 843806 | D14: 859663
... A1524: 43642 | B1524: 9.42 | C1524: 533580 | D1524: 1544006
A1525: 43641 | B1525: 9.4 | C1525: 325385
A1526: 43640 | B1526: 9.36 | C1526: 90602
A1527: 43637 | B1527: 9.6 | C1527: 499448
A1528: 43636 | B1528: 9.37 | C1528: 424425
A1529: 43635 | B1529: 9.35 | C1529: 93875
A1530: 43634 | B1530: 9.41 | C1530: 723887
A1531: 43633 | B1531: 9.45 | C1531: 163636
A1532: 43630 | B1532: 9.5 | C1532: 1167035
A1533: 43629 | B1533: 9.56 | C1533: 227127
A1534: 43628 | B1534: 9.57 | C1534: 233071
A1535: 43627 | B1535: 9.52 | C1535: 401136
A1536: 43626 | B1536: 9.55 | C1536: 903652
... A1538: 43622 | B1538: 10.48 | C1538: 13675814

Sheet NDX
A1: Date | B1: Last Price
A2: 45859
A3: 45856 | B3: 23065.47
A4: 45855 | B4: 23081.05
A5: 45854 | B5: 22907.97
A6: 45853 | B6: 22884.59
A7: 45852 | B7: 22855.63
A8: 45849 | B8: 22780.6
A9: 45848 | B9: 22829.26
A10: 45847 | B10: 22864.91
A11: 45846 | B11: 22702.25
A12: 45845 | B12: 22685.57
A13: 45841 | B13: 22866.97
A14: 45840 | B14: 22641.89
... A2544: 42165 | B2544: 4485.46

Sheet S&P
A1: Date | B1: Last Price
A2: 45859
A3: 45856 | B3: 6296.79
A4: 45855 | B4: 6297.36
A5: 45854 | B5: 6263.7
A6: 45853 | B6: 6243.76
A7: 45852 | B7: 6268.56
A8: 45849 | B8: 6259.75
A9: 45848 | B9: 6280.46
A10: 45847 | B10: 6263.26
A11: 45846 | B11: 6225.52
A12: 45845 | B12: 6229.98
A13: 45841 | B13: 6279.35
A14: 45840 | B14: 6227.42
... A2544: 42165 | B2544: 2105.2

Sheet Data
A1: Date | B1: BIDU | C1: TME | D1: VIPS | E1: FTCH | F1: IQ | G1: PARA | H1: DISCA | I1: GSX | J1: NDX | K1: S&P
A2: 45855 | B2: =INDEX(BIDU!B:B,MATCH(Data!A2,BIDU!A:A,0)) -> 0 | C2: =INDEX(TME!B:B,MATCH(Data!A2,TME!A:A,0)) -> 0 | D2: =INDEX(VIPS!B:B,MATCH(Data!A2,VIPS!A:A,0)) -> 0 | E2: =INDEX(FTCH!B:B,MATCH(Data!A2,FTCH!A:A,0)) -> 0 | F2: =INDEX(IQ!B:B,MATCH(Data!A2,IQ!A:A,0)) -> 0 | G2: =INDEX(Para!B:B,MATCH(Data!A2,Para!A:A,0)) -> #N/A | H2: =INDEX(DISCA!B:B,MATCH(Data!A2,DISCA!A:A,0)) -> #N/A | I2: =INDEX(GSX!B:B,MATCH(Data!A2,GSX!A:A,0)) -> 0 | J2: =INDEX(NDX!B:B,MATCH(Data!A2,NDX!A:A,0)) -> 23081.05 | K2: =INDEX('S&P'!B:B,MATCH(Data!A2,'S&P'!A:A,0)) -> 6297.36
A3: 45854 | B3: =INDEX(BIDU!B:B,MATCH(Data!A3,BIDU!A:A,0)) -> 86.32 | C3: =INDEX(TME!B:B,MATCH(Data!A3,TME!A:A,0)) -> 21.44 | D3: =INDEX(VIPS!B:B,MATCH(Data!A3,VIPS!A:A,0)) -> 15.12 | E3: =INDEX(FTCH!B:B,MATCH(Data!A3,FTCH!A:A,0)) -> 1e-06 | F3: =INDEX(IQ!B:B,MATCH(Data!A3,IQ!A:A,0)) -> 1.86 | G3: =INDEX(Para!B:B,MATCH(Data!A3,Para!A:A,0)) -> #N/A | H3: =INDEX(DISCA!B:B,MATCH(Data!A3,DISCA!A:A,0)) -> #N/A | I3: =INDEX(GSX!B:B,MATCH(Data!A3,GSX!A:A,0)) -> 3.84 | J3: =INDEX(NDX!B:B,MATCH(Data!A3,NDX!A:A,0)) -> 22907.97 | K3: =INDEX('S&P'!B:B,MATCH(Data!A3,'S&P'!A:A,0)) -> 6263.7
A4: 45853 | B4: =INDEX(BIDU!B:B,MATCH(Data!A4,BIDU!A:A,0)) -> 93.3 | C4: =INDEX(TME!B:B,MATCH(Data!A4,TME!A:A,0)) -> 21.29 | D4: =INDEX(VIPS!B:B,MATCH(Data!A4,VIPS!A:A,0)) -> 15.58 | E4: =INDEX(FTCH!B:B,MATCH(Data!A4,FTCH!A:A,0)) -> 1e-06 | F4: =INDEX(IQ!B:B,MATCH(Data!A4,IQ!A:A,0)) -> 1.86 | G4: =INDEX(Para!B:B,MATCH(Data!A4,Para!A:A,0)) -> #N/A | H4: =INDEX(DISCA!B:B,MATCH(Data!A4,DISCA!A:A,0)) -> #N/A | I4: =INDEX(GSX!B:B,MATCH(Data!A4,GSX!A:A,0)) -> 3.99 | J4: =INDEX(NDX!B:B,MATCH(Data!A4,NDX!A:A,0)) -> 22884.59 | K4: =INDEX('S&P'!B:B,MATCH(Data!A4,'S&P'!A:A,0)) -> 6243.76
A5: 45852 | B5: =INDEX(BIDU!B:B,MATCH(Data!A5,BIDU!A:A,0)) -> 85.87 | C5: =INDEX(TME!B:B,MATCH(Data!A5,TME!A:A,0)) -> 20.67 | D5: =INDEX(VIPS!B:B,MATCH(Data!A5,VIPS!A:A,0)) -> 15.11 | E5: =INDEX(FTCH!B:B,MATCH(Data!A5,FTCH!A:A,0)) -> 1e-06 | F5: =INDEX(IQ!B:B,MATCH(Data!A5,IQ!A:A,0)) -> 1.79 | G5: =INDEX(Para!B:B,MATCH(Data!A5,Para!A:A,0)) -> #N/A | H5: =INDEX(DISCA!B:B,MATCH(Data!A5,DISCA!A:A,0)) -> #N/A | I5: =INDEX(GSX!B:B,MATCH(Data!A5,GSX!A:A,0)) -> 3.59 | J5: =INDEX(NDX!B:B,MATCH(Data!A5,NDX!A:A,0)) -> 22855.63 | K5: =INDEX('S&P'!B:B,MATCH(Data!A5,'S&P'!A:A,0)) -> 6268.56
A6: 45849 | B6: =INDEX(BIDU!B:B,MATCH(Data!A6,BIDU!A:A,0)) -> 86.93 | C6: =INDEX(TME!B:B,MATCH(Data!A6,TME!A:A,0)) -> 19.79 | D6: =INDEX(VIPS!B:B,MATCH(Data!A6,VIPS!A:A,0)) -> 15.2 | E6: =INDEX(FTCH!B:B,MATCH(Data!A6,FTCH!A:A,0)) -> 1e-06 | F6: =INDEX(IQ!B:B,MATCH(Data!A6,IQ!A:A,0)) -> 1.83 | G6: =INDEX(Para!B:B,MATCH(Data!A6,Para!A:A,0)) -> #N/A | H6: =INDEX(DISCA!B:B,MATCH(Data!A6,DISCA!A:A,0)) -> #N/A | I6: =INDEX(GSX!B:B,MATCH(Data!A6,GSX!A:A,0)) -> 3.56 | J6: =INDEX(NDX!B:B,MATCH(Data!A6,NDX!A:A,0)) -> 22780.6 | K6: =INDEX('S&P'!B:B,MATCH(Data!A6,'S&P'!A:A,0)) -> 6259.75
A7: 45848 | B7: =INDEX(BIDU!B:B,MATCH(Data!A7,BIDU!A:A,0)) -> 88.44 | C7: =INDEX(TME!B:B,MATCH(Data!A7,TME!A:A,0)) -> 20 | D7: =INDEX(VIPS!B:B,MATCH(Data!A7,VIPS!A:A,0)) -> 15.01 | E7: =INDEX(FTCH!B:B,MATCH(Data!A7,FTCH!A:A,0)) -> 1e-06 | F7: =INDEX(IQ!B:B,MATCH(Data!A7,IQ!A:A,0)) -> 1.83 | G7: =INDEX(Para!B:B,MATCH(Data!A7,Para!A:A,0)) -> #N/A | H7: =INDEX(DISCA!B:B,MATCH(Data!A7,DISCA!A:A,0)) -> #N/A | I7: =INDEX(GSX!B:B,MATCH(Data!A7,GSX!A:A,0)) -> 3.58 | J7: =INDEX(NDX!B:B,MATCH(Data!A7,NDX!A:A,0)) -> 22829.26 | K7: =INDEX('S&P'!B:B,MATCH(Data!A7,'S&P'!A:A,0)) -> 6280.46
A8: 45847 | B8: =INDEX(BIDU!B:B,MATCH(Data!A8,BIDU!A:A,0)) -> 88.66 | C8: =INDEX(TME!B:B,MATCH(Data!A8,TME!A:A,0)) -> 20.35 | D8: =INDEX(VIPS!B:B,MATCH(Data!A8,VIPS!A:A,0)) -> 15.07 | E8: =INDEX(FTCH!B:B,MATCH(Data!A8,FTCH!A:A,0)) -> 1e-06 | F8: =INDEX(IQ!B:B,MATCH(Data!A8,IQ!A:A,0)) -> 1.82 | G8: =INDEX(Para!B:B,MATCH(Data!A8,Para!A:A,0)) -> #N/A | H8: =INDEX(DISCA!B:B,MATCH(Data!A8,DISCA!A:A,0)) -> #N/A | I8: =INDEX(GSX!B:B,MATCH(Data!A8,GSX!A:A,0)) -> 3.65 | J8: =INDEX(NDX!B:B,MATCH(Data!A8,NDX!A:A,0)) -> 22864.91 | K8: =INDEX('S&P'!B:B,MATCH(Data!A8,'S&P'!A:A,0)) -> 6263.26
A9: 45846 | B9: =INDEX(BIDU!B:B,MATCH(Data!A9,BIDU!A:A,0)) -> 90.28 | C9: =INDEX(TME!B:B,MATCH(Data!A9,TME!A:A,0)) -> 20.29 | D9: =INDEX(VIPS!B:B,MATCH(Data!A9,VIPS!A:A,0)) -> 14.96 | E9: =INDEX(FTCH!B:B,MATCH(Data!A9,FTCH!A:A,0)) -> 1e-06 | F9: =INDEX(IQ!B:B,MATCH(Data!A9,IQ!A:A,0)) -> 1.83 | G9: =INDEX(Para!B:B,MATCH(Data!A9,Para!A:A,0)) -> #N/A | H9: =INDEX(DISCA!B:B,MATCH(Data!A9,DISCA!A:A,0)) -> #N/A | I9: =INDEX(GSX!B:B,MATCH(Data!A9,GSX!A:A,0)) -> 3.6 | J9: =INDEX(NDX!B:B,MATCH(Data!A9,NDX!A:A,0)) -> 22702.25 | K9: =INDEX('S&P'!B:B,MATCH(Data!A9,'S&P'!A:A,0)) -> 6225.52
A10: 45845 | B10: =INDEX(BIDU!B:B,MATCH(Data!A10,BIDU!A:A,0)) -> 89.79 | C10: =INDEX(TME!B:B,MATCH(Data!A10,TME!A:A,0)) -> 20.04 | D10: =INDEX(VIPS!B:B,MATCH(Data!A10,VIPS!A:A,0)) -> 14.96 | E10: =INDEX(FTCH!B:B,MATCH(Data!A10,FTCH!A:A,0)) -> 1e-06 | F10: =INDEX(IQ!B:B,MATCH(Data!A10,IQ!A:A,0)) -> 1.77 | G10: =INDEX(Para!B:B,MATCH(Data!A10,Para!A:A,0)) -> #N/A | H10: =INDEX(DISCA!B:B,MATCH(Data!A10,DISCA!A:A,0)) -> #N/A | I10: =INDEX(GSX!B:B,MATCH(Data!A10,GSX!A:A,0)) -> 3.45 | J10: =INDEX(NDX!B:B,MATCH(Data!A10,NDX!A:A,0)) -> 22685.57 | K10: =INDEX('S&P'!B:B,MATCH(Data!A10,'S&P'!A:A,0)) -> 6229.98
A11: 45841 | B11: =INDEX(BIDU!B:B,MATCH(Data!A11,BIDU!A:A,0)) -> 86.35 | C11: =INDEX(TME!B:B,MATCH(Data!A11,TME!A:A,0)) -> 19.46 | D11: =INDEX(VIPS!B:B,MATCH(Data!A11,VIPS!A:A,0)) -> 14.99 | E11: =INDEX(FTCH!B:B,MATCH(Data!A11,FTCH!A:A,0)) -> 1e-06 | F11: =INDEX(IQ!B:B,MATCH(Data!A11,IQ!A:A,0)) -> 1.78 | G11: =INDEX(Para!B:B,MATCH(Data!A11,Para!A:A,0)) -> #N/A | H11: =INDEX(DISCA!B:B,MATCH(Data!A11,DISCA!A:A,0)) -> #N/A | I11: =INDEX(GSX!B:B,MATCH(Data!A11,GSX!A:A,0)) -> 3.53 | J11: =INDEX(NDX!B:B,MATCH(Data!A11,NDX!A:A,0)) -> 22866.97 | K11: =INDEX('S&P'!B:B,MATCH(Data!A11,'S&P'!A:A,0)) -> 6279.35
A12: 45840 | B12: =INDEX(BIDU!B:B,MATCH(Data!A12,BIDU!A:A,0)) -> 86.44 | C12: =INDEX(TME!B:B,MATCH(Data!A12,TME!A:A,0)) -> 19.17 | D12: =INDEX(VIPS!B:B,MATCH(Data!A12,VIPS!A:A,0)) -> 15.07 | E12: =INDEX(FTCH!B:B,MATCH(Data!A12,FTCH!A:A,0)) -> 1e-06 | F12: =INDEX(IQ!B:B,MATCH(Data!A12,IQ!A:A,0)) -> 1.75 | G12: =INDEX(Para!B:B,MATCH(Data!A12,Para!A:A,0)) -> #N/A | H12: =INDEX(DISCA!B:B,MATCH(Data!A12,DISCA!A:A,0)) -> #N/A | I12: =INDEX(GSX!B:B,MATCH(Data!A12,GSX!A:A,0)) -> 3.58 | J12: =INDEX(NDX!B:B,MATCH(Data!A12,NDX!A:A,0)) -> 22641.89 | K12: =INDEX('S&P'!B:B,MATCH(Data!A12,'S&P'!A:A,0)) -> 6227.42
A13: 45839 | B13: =INDEX(BIDU!B:B,MATCH(Data!A13,BIDU!A:A,0)) -> 86.04 | C13: =INDEX(TME!B:B,MATCH(Data!A13,TME!A:A,0)) -> 19.24 | D13: =INDEX(VIPS!B:B,MATCH(Data!A13,VIPS!A:A,0)) -> 15.1 | E13: =INDEX(FTCH!B:B,MATCH(Data!A13,FTCH!A:A,0)) -> 1e-06 | F13: =INDEX(IQ!B:B,MATCH(Data!A13,IQ!A:A,0)) -> 1.76 | G13: =INDEX(Para!B:B,MATCH(Data!A13,Para!A:A,0)) -> #N/A | H13: =INDEX(DISCA!B:B,MATCH(Data!A13,DISCA!A:A,0)) -> #N/A | I13: =INDEX(GSX!B:B,MATCH(Data!A13,GSX!A:A,0)) -> 3.58 | J13: =INDEX(NDX!B:B,MATCH(Data!A13,NDX!A:A,0)) -> 22478.14 | K13: =INDEX('S&P'!B:B,MATCH(Data!A13,'S&P'!A:A,0)) -> 6198.01
... A1538: 43622 | B1538: =INDEX(BIDU!B:B,MATCH(Data!A1538,BIDU!A:A,0)) -> 108.89 | C1538: =INDEX(TME!B:B,MATCH(Data!A1538,TME!A:A,0)) -> 13.2 | D1538: =INDEX(VIPS!B:B,MATCH(Data!A1538,VIPS!A:A,0)) -> 7.01 | E1538: =INDEX(FTCH!B:B,MATCH(Data!A1538,FTCH!A:A,0)) -> 19.780001 | F1538: =INDEX(IQ!B:B,MATCH(Data!A1538,IQ!A:A,0)) -> 17.91 | G1538: =INDEX(Para!B:B,MATCH(Data!A1538,Para!A:A,0)) -> 48.44 | H1538: =INDEX(DISCA!B:B,MATCH(Data!A1538,DISCA!A:A,0)) -> #N/A | I1538: =INDEX(GSX!B:B,MATCH(Data!A1538,GSX!A:A,0)) -> 10.48 | J1538: =INDEX(NDX!B:B,MATCH(Data!A1538,NDX!A:A,0)) -> 7275.93 | K1538: =INDEX('S&P'!B:B,MATCH(Data!A1538,'S&P'!A:A,0)) -> 2843.49

Sheet Data6m
A1: Date | B1: BIDU | C1: TME | D1: VIPS | E1: FTCH | F1: IQ | G1: PARA | H1: DISCA | I1: GSX | J1: NDX | K1: S&P
A2: 44277 | B2: 266.13 | C2: 30.87 | D2: 45.25 | E2: 62 | F2: 28.04 | G2: 100.34 | H2: 74.65 | I2: 83.79 | J2: 13086.51 | K2: 3940.59
A3: 44274 | B3: 257.47 | C3: 30.42 | D3: 45.45 | E3: 59.880001 | F3: 27.77 | G3: 97.35 | H3: 77.27 | I3: 86.6 | J3: 12866.99 | K3: 3913.1
A4: 44273 | B4: 264.85 | C4: 28.52 | D4: 44.46 | E4: 59.5 | F4: 26.63 | G4: 96.76 | H4: 75.95 | I4: 89.68 | J4: 12789.14 | K4: 3915.46
A5: 44272 | B5: 277.13 | C5: 27.9 | D5: 44.11 | E5: 60.77 | F5: 26.03 | G5: 92.34 | H5: 74.07 | I5: 92.67 | J5: 13202.38 | K5: 3974.12
A6: 44271 | B6: 266.78 | C6: 26.45 | D6: 42.92 | E6: 59.25 | F6: 25.5 | G6: 96.24 | H6: 75.81 | I6: 89.3 | J6: 13152.28 | K6: 3962.71
A7: 44270 | B7: 265.53 | C7: 26.36 | D7: 41.7 | E7: 58.259998 | F7: 25.14 | G7: 96.33 | H7: 73.67 | I7: 89.16 | J7: 13082.54 | K7: 3968.94
A8: 44267 | B8: 264.25 | C8: 26.49 | D8: 42.2 | E8: 59.5 | F8: 26.44 | G8: 94.94 | H8: 71.1 | I8: 84.88 | J8: 12937.29 | K8: 3943.34
A9: 44266 | B9: 272.38 | C9: 27.78 | D9: 42.41 | E9: 59.84 | F9: 27.69 | G9: 86.28 | H9: 66.97 | I9: 82.05 | J9: 13052.9 | K9: 3939.34
A10: 44265 | B10: 255.14 | C10: 27.35 | D10: 42.01 | E10: 56.470001 | F10: 27.83 | G10: 82.89 | H10: 65.82 | I10: 81.01 | J10: 12752.07 | K10: 3898.81
A11: 44264 | B11: 264.28 | C11: 26.69 | D11: 41.59 | E11: 56.240002 | F11: 27.09 | G11: 79.66 | H11: 63.01 | I11: 88.62 | J11: 12794.49 | K11: 3875.44
A12: 44263 | B12: 232.68 | C12: 25.32 | D12: 40.64 | E12: 53.5 | F12: 25.76 | G12: 83.66 | H12: 67.25 | I12: 85.94 | J12: 12299.08 | K12: 3821.35
A13: 44260 | B13: 261.72 | C13: 26.15 | D13: 41.22 | E13: 55.509998 | F13: 26.07 | G13: 74.24 | H13: 64.25 | I13: 91.39 | J13: 12668.51 | K13: 3841.94
... A205: 43983 | B205: 107.1 | C205: 12.6 | D205: 17.14 | E205: 13.92 | F205: 16.7 | G205: 21.53 | H205: 21.95 | I205: 32.61 | J205: 9598.89 | K205: 3055.73
B207: =B2/B205 -> 2.4848739 | C207: =C2/C205 -> 2.45 | D207: =D2/D205 -> 2.6400233 | E207: =E2/E205 -> 4.454023 | F207: =F2/F205 -> 1.6790419 | G207: =G2/G205 -> 4.6604738 | H207: =H2/H205 -> 3.4009112 | I207: =I2/I205 -> 2.5694572

Sheet DataSnipper
A1: DataSnipper
A2: The following documents are contained in this workbook. | D2: =HYPERLINK("https://knowledge.datasnipper.com/", "Knowledge Base") -> Knowledge Base
A4: File name | B4: Imported at | C4: Imported by | D4: File path | E4: File size in MB | F4: Total pages
A5: imported image (0).png.pdf | B5: 45999 | C5: Thomas Pink | E5: 0.13 | F5: 1
A6: imported image (1).png.pdf | B6: 45999 | C6: Thomas Pink | E6: 0.14 | F6: 1
A7: imported image (2).png.pdf | B7: 45999 | C7: Thomas Pink | E7: 0.14 | F7: 1
A8: imported image (3).png.pdf | B8: 45999 | C8: Thomas Pink | E8: 0.13 | F8: 1
A9: imported image (4).png.pdf | B9: 45999 | C9: Thomas Pink | E9: 0.13 | F9: 1
A10: imported image (5).png.pdf | B10: 45999 | C10: Thomas Pink | E10: 0.12 | F10: 1
A11: imported image (6).png.pdf | B11: 45999 | C11: Thomas Pink | E11: 0.13 | F11: 1
A12: imported image (7).png.pdf | B12: 45999 | C12: Thomas Pink | E12: 0.13 | F12: 1
A13: imported image (8).png.pdf | B13: 45999 | C13: Thomas Pink | E13: 0.13 | F13: 1
A14: imported image (9).png.pdf | B14: 45999 | C14: Thomas Pink | E14: 0.12 | F14: 1
